{"message":"Something went wrong, try again!","success":false,"response":{"traceback":"Traceback (most recent call last):\n  File \"/home/GetLinkBackend/venv/lib/python3.12/site-packages/django/db/models/fields/__init__.py\", line 2123, in get_prep_value\n    return int(value)\n           ^^^^^^^^^^\nValueError: invalid literal for int() with base 10: 'abc'\n\nThe above exception was the direct cause of the following exception:\n\nTraceback (most recent call last):\n  File \"/home/GetLinkBackend/helpers/utils/advice.py\", line 25, in wrapper\n    return func(*args, **kwargs)\n           ^^^^^^^^^^^^^^^^^^^^^\n  File \"/home/GetLinkBackend/talent_dashboard/views.py\", line 2700, in destroy\n    cv_instance = CoverLetterCreation.objects.get(id=cv_id)\n                  ^^^^^^^^^^^^^^^^^^^^^^^^^^^^^^^^^^^^^^^^^\n  File \"/home/GetLinkBackend/venv/lib/python3.12/site-packages/django/db/models/manager.py\", line 87, in manager_method\n    return getattr(self.get_queryset(), name)(*args, **kwargs)\n           ^^^^^^^^^^^^^^^^^^^^^^^^^^^^^^^^^^^^^^^^^^^^^^^^^^^\n  File \"/home/GetLinkBackend/venv/lib/python3.12/site-packages/django/db/models/query.py\", line 635, in get\n    clone = self._chain() if self.query.combinator else self.filter(*args, **kwargs)\n                                                        ^^^^^^^^^^^^^^^^^^^^^^^^^^^^\n  File \"/home/GetLinkBackend/venv/lib/python3.12/site-packages/django/db/models/query.py\", line 1476, in filter\n    return self._filter_or_exclude(False, args, kwargs)\n           ^^^^^^^^^^^^^^^^^^^^^^^^^^^^^^^^^^^^^^^^^^^^\n  File \"/home/GetLinkBackend/venv/lib/python3.12/site-packages/django/db/models/query.py\", line 1494, in _filter_or_exclude\n    clone._filter_or_exclude_inplace(negate, args, kwargs)\n  File \"/home/GetLinkBackend/venv/lib/python3.12/site-packages/django/db/models/query.py\", line 1501, in _filter_or_exclude_inplace\n    self._query.add_q(Q(*args, **kwargs))\n  File \"/home/GetLinkBackend/venv/lib/python3.12/site-packages/django/db/models/sql/query.py\", line 1609, in add_q\n    clause, _ = self._add_q(q_object, self.used_aliases)\n                ^^^^^^^^^^^^^^^^^^^^^^^^^^^^^^^^^^^^^^^^\n  File \"/home/GetLinkBackend/venv/lib/python3.12/site-packages/django/db/models/sql/query.py\", line 1641, in _add_q\n    child_clause, needed_inner = self.build_filter(\n                                 ^^^^^^^^^^^^^^^^^^\n  File \"/home/GetLinkBackend/venv/lib/python3.12/site-packages/django/db/models/sql/query.py\", line 1555, in build_filter\n    condition = self.build_lookup(lookups, col, value)\n                ^^^^^^^^^^^^^^^^^^^^^^^^^^^^^^^^^^^^^^\n  File \"/home/GetLinkBackend/venv/lib/python3.12/site-packages/django/db/models/sql/query.py\", line 1385, in build_lookup\n    lookup = lookup_class(lhs, rhs)\n             ^^^^^^^^^^^^^^^^^^^^^^\n  File \"/home/GetLinkBackend/venv/lib/python3.12/site-packages/django/db/models/lookups.py\", line 30, in __init__\n    self.rhs = self.get_prep_lookup()\n               ^^^^^^^^^^^^^^^^^^^^^^\n  File \"/home/GetLinkBackend/venv/lib/python3.12/site-packages/django/db/models/lookups.py\", line 369, in get_prep_lookup\n    return super().get_prep_lookup()\n           ^^^^^^^^^^^^^^^^^^^^^^^^^\n  File \"/home/GetLinkBackend/venv/lib/python3.12/site-packages/django/db/models/lookups.py\", line 88, in get_prep_lookup\n    return self.lhs.output_field.get_prep_value(self.rhs)\n           ^^^^^^^^^^^^^^^^^^^^^^^^^^^^^^^^^^^^^^^^^^^^^^\n  File \"/home/GetLinkBackend/venv/lib/python3.12/site-packages/django/db/models/fields/__init__.py\", line 2125, in get_prep_value\n    raise e.__class__(\nValueError: Field 'id' expected a number but got 'abc'.\n"}}